Workbook

Sheet Protocol

Sheet Mix calculations
A1: Tracermix | M1: Bradford mix | N1: 44990
A2: General: | M2: Samples from curve: | N2: 16
A3: Basis: | B3: 50 mmol/L Phosphate buffer + 1 mM EDTA + 10 mM DTT | M3: Samples from assay: | N3: 8
A4: Number of samples: | B4: 10 | E4: Per tracermix! | G4: t3/t4 | M4: Total: | N4: =SUM(N2:N3)+P5 -> 28 | P4: Blanco | Q4: buffer (samples) en water (reagens)
A5: Volume of tracermix: | B5: 50 | C5: µl | P5: 4
A6: CPM per sample: | B6: 200000 | C6: CPM | M6: Make extra mix: | N6: 34
A8: Total volume: | B8: =B5*B4 -> 500 | C8: µl | M8: Total volume needed: | N8: =N6*0.25 -> 8.5 | O8: ml
M9: Reagens (5X conc): | N9: =N8/5 -> 1.7 | O9: ml
A10: Radioactive tracer T3: | M10: Water: | N10: =N8-N9 -> 6.8 | O10: ml
A11: Total of CPM needed: | B11: =B6*B4 -> 2000000
A12: Tracer activity: | B12: =402666/5 -> 80533.2 | C12: CPM/µl | M12: Proceed according protocol:
A13: Add to mix: | B13: =B11/B12 -> 24.834478 | C13: --> Add 10% more = | E13: =B13*1.1 -> 27.317926 | F13: µl
M14: 1. Make standard curve*: 1 - 0,8 - 0,6 - 0,4 - 0,2 - 0 mg/ml BSA.
A15: Radioactive tracer t4: | M15: 2. Dilute 5X Biorad protein acid to a 1X solution in water.
A16: Total of CPM needed: | B16: =B6*B4 -> 2000000 | M16: 3. Pipette 5uL of your samples and standards in a 96 well ELISA plate.
A17: Tracer activity: | B17: =749709/5 -> 149941.8 | C17: CPM/µl | M17: 4. Add 250µl Bradford reagens, wait 3-6 minutes and read the plate at 598nm.
A18: Add to mix: | B18: =B16/B17 -> 13.338509 | C18: --> Add 10% more = | E18: =B18*1.1 -> 14.67236 | M18: 5. Calculate the amount of protein (manually standard curve and all samples minus blanc) remembering to correct your samples for dilution giving amount of protein in mg/ml
A20: Cold TH: | M20: * This can be done before hand and be alliquoted, freezing and thawing causes degradation of the protein by NaOH.
A21: Stock: | B21: 1 | C21: µM | D21: (Original stock is 10µM, diluted 10 times for easier pipetting) | M21: Make curve in 0.1M NaOH, PBS or H2O but it should always be similar to the liquid your sample is in.
A22: Final of tracermix: | B22: 2 | C22: nM | D22: (Final in sample = 1nM when 50µl tracermix is added to 50µl sample)
A23: Add cold 1:500 = | B23: =(B8*2)/500 -> 2 | C23: µl
M24: concentration curve | N24: nu 2, 1.5, 1 0.75, 0.5, 0.25, 0.125, 0 mg/ml | R24: in water (want matcht beter met de phosphate buffer)
A25: DTT | M25: 1 | N25: 2 | O25: 3 | P25: 4 | Q25: 5 | R25: 6 | S25: 7 | T25: 8 | U25: 9 | V25: 10 | W25: 11 | X25: 12
A26: Volume (incl. wash): | B26: 8 | C26: ml | L26: A | M26: BSA 2 mg/mL | N26: BSA 2 mg/mL | P26: SK T3 1-1 | Q26: SK T3 1-2
A27: Stock: | B27: 1 | C27: M | L27: B | M27: BSA 1.5 mg/mL | N27: BSA 1.5 mg/mL | P27: SK T3 2-1 | Q27: SK T3 2-2
A28: Final: | B28: 10 | C28: mM | L28: C | M28: BSA 1 mg/mL | N28: BSA 1 mg/mL | P28: SK T4 1-1 | Q28: SK T4 1-2
A29: Add DTT 1:100 = | B29: =((B26*1000)*B28)/(B27*1000) -> 80 | C29: µl | L29: D | M29: BSA 0.75 mg/mL | N29: BSA 0.75 mg/mL | P29: SK T4 2-1 | Q29: SK T4 2-2
L30: E | M30: BSA 0.5 mg/mL | N30: BSA 0.5 mg/mL
A31: IOP | L31: F | M31: BSA 0.25 mg/mL | N31: BSA 0.25 mg/mL
A32: Stock | B32: 10 | C32: mM | L32: G | M32: BSA 0.125 mg/mL | N32: BSA 0.125 mg/mL
A33: Final concentration | B33: 0.2 | C33: mM | L33: H | M33: BSA 0 mg/mL | N33: BSA 0 mg/mL
A34: Volume of tracer mix with IOP | B34: 100 | C34: µl
A35: Add to mix | B35: =(B33*B34)/B32 -> 2 | C35: µl | M35: T3 1 -1 &-2 zijn duplo uit de epp die gesonificeerd zijn uit een well | U35: (duplo bradford uit een well)
M37: de T3 1 & 2 zijn de verschllende wellen waar dan de metabolisme assays op zijn gebaseerd | U37: (well)

Sheet Protein concentration
A1: Bradford plate readout
A2: 1.534 | B2: 1.003 | D2: 0.816 | E2: 0.823
A3: 1.311 | B3: 1.36 | D3: 0.819 | E3: 0.814
A4: 1.005 | B4: 1.023 | D4: 0.83 | E4: 0.862
A5: 0.957 | B5: 1.021 | D5: 0.841 | E5: 0.861
A6: 0.779 | B6: 0.78
A7: 0.522 | B7: 0.535
A8: 0.447 | B8: 0.489
A9: 0.363 | B9: 0.363 | L9: 0.045
A11: Standard curve
A12: mg/ml BSA | B12: A | C12: B | D12: Average | E12: Average - blanco | O12: Samples have to fit in curve, if not dilute them | U12: Dit niet gebruiken!
A13: 2 | B13: 1.534 | C13: 1.003 | D13: =AVERAGE(B13:C13) -> 1.2685 | F13: not included
A14: 1.5 | B14: 1.311 | C14: 1.36 | D14: =AVERAGE(B14:C14) -> 1.3355 | E14: =D14-$D$20 -> 0.9725 | O14: Samples dilution 1:5 --> 2 wells in 300µl phosphate buffer
A15: 1 | B15: 1.005 | C15: 1.023 | D15: =AVERAGE(B15:C15) -> 1.014 | O15: In plate = 250µl Bradford + 5µl Sample
A16: 0.75 | B16: 0.957 | C16: 1.021 | D16: =AVERAGE(B16:C16) -> 0.989
A17: 0.5 | B17: 0.779 | C17: 0.78 | D17: =AVERAGE(B17:C17) -> 0.7795 | O17: Dilution when scraping: | R17: 5
A18: 0.25 | B18: 0.522 | C18: 0.535 | D18: =AVERAGE(B18:C18) -> 0.5285 | O18: Dilution for bradford: | R18: 1 | S18: (if samples are higher then the curve)
A19: 0.125 | B19: 0.447 | C19: 0.489 | D19: =AVERAGE(B19:C19) -> 0.468 | O19: Total dilution: | R19: =R17*R18 -> 5
A20: 0 | B20: 0.363 | C20: 0.363 | D20: =AVERAGE(B20:C20) -> 0.363
G24: =SLOPE(D16:D20,A16:A20) -> 0.84282759 | H24: slope
G25: =INTERCEPT(D16:D20,A16:A20) -> 0.35168103 | H25: intercept | L25: =LINEST(D13:D20,A13:A20,1,1) -> 0.49590945 | M25: 0.3302
K26: average
H27: Phosphate buffer + EDTA + DTT | K27: =AVERAGE(I3:I5) -> #DIV/0!
A30: Protein concentration in sample
A31: Sample | B31: A | C31: B | D31: Average | E31: Conc. (mg/ml)
A32: SK T3 1 | B32: 0.816 | C32: 0.823 | D32: =AVERAGE(B32:C32) -> 0.8195 | E32: =(D32-$G$25)/$G$24 -> 0.55505891
A33: SK T3 2 | B33: 0.819 | C33: 0.814 | D33: =AVERAGE(B33:C33) -> 0.8165 | E33: =(D33-$G$25)/$G$24 -> 0.55149947
A34: SK T4 1 | B34: 0.83 | C34: 0.862 | D34: =AVERAGE(B34:C34) -> 0.846 | E34: =(D34-$G$25)/$G$24 -> 0.5865007
A35: SK T4 2 | B35: 0.841 | C35: 0.861 | D35: =AVERAGE(B35:C35) -> 0.851 | E35: =(D35-$G$25)/$G$24 -> 0.59243311
D36: =AVERAGE(B36:C36) -> #DIV/0! | E36: =(D36-$G$25)/$G$24 -> #DIV/0!
D37: =AVERAGE(B37:C37) -> #DIV/0! | E37: =(D37-$G$25)/$G$24 -> #DIV/0!
D38: =AVERAGE(B38:C38) -> #DIV/0! | E38: =(D38-$G$25)/$G$24 -> #DIV/0!
D39: =AVERAGE(B39:C39) -> #DIV/0! | E39: =(D39-$G$25)/$G$24 -> #DIV/0!
D40: =AVERAGE(B40:C40) -> #DIV/0! | E40: =(D40-$G$25)/$G$24 -> #DIV/0!
D41: =AVERAGE(B41:C41) -> #DIV/0! | E41: =(D41-$G$25)/$G$24 -> #DIV/0!
D42: =AVERAGE(B42:C42) -> #DIV/0! | E42: =(D42-$G$25)/$G$24 -> #DIV/0!
D43: =AVERAGE(B43:C43) -> #DIV/0! | E43: =(D43-$G$25)/$G$24 -> #DIV/0!
D44: =AVERAGE(B44:C44) -> #DIV/0! | E44: =(D44-$G$25)/$G$24 -> #DIV/0!
D45: =AVERAGE(B45:C45) -> #DIV/0! | E45: =(D45-$G$25)/$G$24 -> #DIV/0!
D46: =AVERAGE(B46:C46) -> #DIV/0! | E46: =(D46-$G$25)/$G$24 -> #DIV/0!
...

Sheet Conversion Deio2
A1: 08/06/2021 NPC WTC1c
A2: Name | B2: I (1.3) | C2: T1 (2.9) | D2: 3,3'-T2 (5.7) | E2: T3 (8.1) | F2: rT3 (8.9) | G2: T4 (11.5) | H2: Som | J2: %I | K2: %T1 | L2: %T2 | M2: %T3 | N2: %rT3 | O2: %T4
A3: T4 Tracer A | G3: 5634970 | H3: =SUM(B3:G3) -> 5634970 | J3: =(B3/H3)*100 -> 0 | K3: =(C3/H3)*100 -> 0 | L3: =(D3/H3)*100 -> 0 | M3: =(E3/H3)*100 -> 0 | N3: =(F3/H3)*100 -> 0 | O3: =(G3/H3)*100 -> 100
A4: T4 Tracer B | G4: 5868553 | H4: =SUM(B4:G4) -> 5868553 | J4: =(B4/H4)*100 -> 0 | K4: =(C4/H4)*100 -> 0 | L4: =(D4/H4)*100 -> 0 | M4: =(E4/H4)*100 -> 0 | N4: =(F4/H4)*100 -> 0 | O4: =(G4/H4)*100 -> 100
A5: SK 1-1 | G5: 5347995 | H5: =SUM(B5:G5) -> 5347995 | J5: =(B5/H5)*100 -> 0 | K5: =(C5/H5)*100 -> 0 | L5: =(D5/H5)*100 -> 0 | M5: =(E5/H5)*100 -> 0 | N5: =(F5/H5)*100 -> 0 | O5: =(G5/H5)*100 -> 100
A6: SK1-2 | G6: 5523338 | H6: =SUM(B6:G6) -> 5523338 | J6: =(B6/H6)*100 -> 0 | K6: =(C6/H6)*100 -> 0 | L6: =(D6/H6)*100 -> 0 | M6: =(E6/H6)*100 -> 0 | N6: =(F6/H6)*100 -> 0 | O6: =(G6/H6)*100 -> 100
A7: SK 2-1 | G7: 5113984 | H7: =SUM(B7:G7) -> 5113984 | J7: =(B7/H7)*100 -> 0 | K7: =(C7/H7)*100 -> 0 | L7: =(D7/H7)*100 -> 0 | M7: =(E7/H7)*100 -> 0 | N7: =(F7/H7)*100 -> 0 | O7: =(G7/H7)*100 -> 100
A8: SK 2-2 | G8: 5563731 | H8: =SUM(B8:G8) -> 5563731 | J8: =(B8/H8)*100 -> 0 | K8: =(C8/H8)*100 -> 0 | L8: =(D8/H8)*100 -> 0 | M8: =(E8/H8)*100 -> 0 | N8: =(F8/H8)*100 -> 0 | O8: =(G8/H8)*100 -> 100 | AB8: ='Conversion Deio2'!M8\ -> #NAME?
H9: =SUM(B9:G9) -> 0 | J9: =(B9/H9)*100 -> #DIV/0! | K9: =(C9/H9)*100 -> #DIV/0! | L9: =(D9/H9)*100 -> #DIV/0! | M9: =(E9/H9)*100 -> #DIV/0! | N9: =(F9/H9)*100 -> #DIV/0! | O9: =(G9/H9)*100 -> #DIV/0!
H10: =SUM(B10:G10) -> 0 | J10: =(B10/H10)*100 -> #DIV/0! | K10: =(C10/H10)*100 -> #DIV/0! | L10: =(D10/H10)*100 -> #DIV/0! | M10: =(E10/H10)*100 -> #DIV/0! | N10: =(G3/H10)*100 -> #DIV/0! | O10: =(G10/H10)*100 -> #DIV/0!
H11: =SUM(B11:G11) -> 0 | J11: =(B11/H11)*100 -> #DIV/0! | K11: =(C11/H11)*100 -> #DIV/0! | L11: =(D11/H11)*100 -> #DIV/0! | M11: =(E11/H11)*100 -> #DIV/0! | N11: =(F11/H11)*100 -> #DIV/0! | O11: =(G11/H11)*100 -> #DIV/0!
H12: =SUM(B12:G12) -> 0 | J12: =(B12/H12)*100 -> #DIV/0! | K12: =(C12/H12)*100 -> #DIV/0! | L12: =(D12/H12)*100 -> #DIV/0! | M12: =(E12/H12)*100 -> #DIV/0! | N12: =(F12/H12)*100 -> #DIV/0! | O12: =(G12/H12)*100 -> #DIV/0!
H13: =SUM(B13:G13) -> 0 | J13: =(B13/H13)*100 -> #DIV/0! | K13: =(C13/H13)*100 -> #DIV/0! | L13: =(D13/H13)*100 -> #DIV/0! | M13: =(E13/H13)*100 -> #DIV/0! | N13: =(F13/H13)*100 -> #DIV/0! | O13: =(G13/H13)*100 -> #DIV/0!
H14: =SUM(B14:G14) -> 0 | J14: =(B14/H14)*100 -> #DIV/0! | K14: =(C14/H14)*100 -> #DIV/0! | L14: =(D14/H14)*100 -> #DIV/0! | M14: =(E14/H14)*100 -> #DIV/0! | N14: =(F14/H14)*100 -> #DIV/0! | O14: =(G14/H14)*100 -> #DIV/0!
H15: =SUM(B15:G15) -> 0 | J15: =(B15/H15)*100 -> #DIV/0! | K15: =(C15/H15)*100 -> #DIV/0! | L15: =(D15/H15)*100 -> #DIV/0! | M15: =(E15/H15)*100 -> #DIV/0! | N15: =(F15/H15)*100 -> #DIV/0! | O15: =(G15/H15)*100 -> #DIV/0!
H16: =SUM(B16:G16) -> 0 | J16: =(B16/H16)*100 -> #DIV/0! | K16: =(C16/H16)*100 -> #DIV/0! | L16: =(D16/H16)*100 -> #DIV/0! | M16: =(E16/H16)*100 -> #DIV/0! | N16: =(F16/H16)*100 -> #DIV/0! | O16: =(G16/H16)*100 -> #DIV/0!
H17: =SUM(B17:G17) -> 0 | J17: =(B17/H17)*100 -> #DIV/0! | K17: =(C17/H17)*100 -> #DIV/0! | L17: =(D17/H17)*100 -> #DIV/0! | M17: =(E17/H17)*100 -> #DIV/0! | N17: =(F17/H17)*100 -> #DIV/0! | O17: =(G17/H17)*100 -> #DIV/0!
H18: =SUM(B18:G18) -> 0 | J18: =(B18/H18)*100 -> #DIV/0! | K18: =(C18/H18)*100 -> #DIV/0! | L18: =(D18/H18)*100 -> #DIV/0! | M18: =(E18/H18)*100 -> #DIV/0! | N18: =(F18/H18)*100 -> #DIV/0! | O18: =(G18/H18)*100 -> #DIV/0!
H19: =SUM(B19:G19) -> 0 | J19: =(B19/H19)*100 -> #DIV/0! | K19: =(C19/H19)*100 -> #DIV/0! | L19: =(D19/H19)*100 -> #DIV/0! | M19: =(E19/H19)*100 -> #DIV/0! | N19: =(F19/H19)*100 -> #DIV/0! | O19: =(G19/H19)*100 -> #DIV/0!
H20: =SUM(B20:G20) -> 0 | J20: =(B20/H20)*100 -> #DIV/0! | K20: =(C20/H20)*100 -> #DIV/0! | L20: =(D20/H20)*100 -> #DIV/0! | M20: =(E20/H20)*100 -> #DIV/0! | N20: =(F20/H20)*100 -> #DIV/0! | O20: =(G20/H20)*100 -> #DIV/0!

Sheet Analysis D2
A2: sample | C2: Time incubation (min) | D2: dilution | E2: protein concentration mg/ml | I2: %Ia | J2: %Ib | K2: %Iav | L2: %Inet A | M2: %Inet B | N2: %Inet avg | O2: %T1a | P2: %T1b | Q2: %T1av | R2: %T1net A | S2: %T1net B | T2: %T1net avg | U2: %T2a | V2: %T2b | W2: %T2av | X2: %T2net A | Y2: %T2net B | Z2: %T2net avg | AA2: %T3a | AB2: %T3b | AC2: %T3av | AD2: %T3net A | AE2: %T3net B | AF2: %T3net avg | AG2: %rT3a | AH2: %rT3b | AI2: %rT3av | AJ2: %rT3net A | AK2: %rT3net B | AL2: %rT3net avg | AM2: %T4a | AN2: %T4b | AO2: %T4av | AP2: %T4net A | AQ2: %T4net B | AR2: %T4net avg
B4: Tracer | I4: ='Conversion Deio2'!J3 -> 0 | J4: ='Conversion Deio2'!J4 -> 0 | K4: =AVERAGE(I4) -> 0 | O4: ='Conversion Deio2'!K3 -> 0 | P4: ='Conversion Deio2'!K4 -> 0 | Q4: =AVERAGE(O4:P4) -> 0 | U4: ='Conversion Deio2'!L3 -> 0 | V4: ='Conversion Deio2'!L4 -> 0 | W4: =AVERAGE(U4) -> 0 | AA4: ='Conversion Deio2'!M3 -> 0 | AB4: ='Conversion Deio2'!M4 -> 0 | AC4: =AVERAGE(AA4) -> 0 | AG4: ='Conversion Deio2'!N3 -> 0 | AH4: ='Conversion Deio2'!N4 -> 0 | AI4: =AVERAGE(AG4:AH4) -> 0 | AM4: ='Conversion Deio2'!O3 -> 100 | AN4: ='Conversion Deio2'!O4 -> 100 | AO4: =AVERAGE(AM4:AN4) -> 100
H5: SD | K5: =_xlfn.STDEV.S(I4:J4) -> 0
A6: 1 | B6: SKNAS 1 | C6: 120 | F6: ='Protein concentration'!E34 -> 0.5865007 | I6: ='Conversion Deio2'!J5 -> 0 | J6: ='Conversion Deio2'!J6 -> 0 | K6: =AVERAGE(I6:J6) -> 0 | L6: =I6-$K$4 -> 0 | M6: =J6-$K$4 -> 0 | N6: =K6-$K$4 -> 0 | O6: ='Conversion Deio2'!K5 -> 0 | P6: ='Conversion Deio2'!K6 -> 0 | Q6: =AVERAGE(O6:P6) -> 0 | R6: =O6-$Q$4 -> 0 | S6: =P6-$Q$4 -> 0 | T6: =Q6-$Q$4 -> 0 | U6: ='Conversion Deio2'!L5 -> 0 | V6: ='Conversion Deio2'!L6 -> 0 | W6: =AVERAGE(U6:V6) -> 0 | X6: =U6-$W$4 -> 0 | Y6: =V6-$W$4 -> 0 | Z6: =AVERAGE(W6-$W$4) -> 0 | AA6: ='Conversion Deio2'!M5 -> 0 | AB6: ='Conversion Deio2'!M6 -> 0 | AC6: =AVERAGE(AA6:AB6) -> 0 | AD6: =AA6-$AC$4 -> 0 | AE6: =AB6-$AC$4 -> 0 | AF6: =AC6-$AC$4 -> 0 | AG6: ='Conversion Deio2'!N5 -> 0 | AH6: ='Conversion Deio2'!N6 -> 0 | AI6: =AVERAGE(AG6:AH6) -> 0 | AJ6: =AG6-$AI$4 -> 0 | AK6: =AH6-$AI$4 -> 0 | AL6: =AI6-$AI$4 -> 0 | AM6: ='Conversion Deio2'!O5 -> 100 | AN6: ='Conversion Deio2'!O6 -> 100 | AO6: =AVERAGE(AM6:AN6) -> 100 | AP6: =AM6-$AO$4 -> 0 | AQ6: =AN6-$AO$4 -> 0 | AR6: =AO6-$AO$4 -> 0
H7: SD | K7: =_xlfn.STDEV.S(I6:J6) -> 0 | N7: =_xlfn.STDEV.S(L6:M6) -> 0 | Q7: =_xlfn.STDEV.S(O6:P6) -> 0 | T7: =_xlfn.STDEV.S(R6:S6) -> 0 | W7: =_xlfn.STDEV.S(U6:V6) -> 0 | Z7: =_xlfn.STDEV.S(X6:Y6) -> 0 | AC7: =_xlfn.STDEV.S(AA6:AB6) -> 0 | AF7: =_xlfn.STDEV.S(AD6:AE6) -> 0 | AI7: =_xlfn.STDEV.S(AG6:AH6) -> 0 | AL7: =_xlfn.STDEV.S(AJ6:AK6) -> 0 | AO7: =_xlfn.STDEV.S(AM6:AN6) -> 0 | AR7: =_xlfn.STDEV.S(AP6:AQ6) -> 0
A8: 2 | B8: SKNAS 2 | C8: 120 | F8: ='Protein concentration'!E35 -> 0.59243311 | I8: ='Conversion Deio2'!J7 -> 0 | J8: ='Conversion Deio2'!J8 -> 0 | K8: =AVERAGE(I8:J8) -> 0 | L8: =I8-$K$4 -> 0 | M8: =J8-$K$4 -> 0 | N8: =K8-$K$4 -> 0 | O8: ='Conversion Deio2'!K7 -> 0 | P8: ='Conversion Deio2'!K8 -> 0 | Q8: =AVERAGE(O8:P8) -> 0 | R8: =O8-$Q$4 -> 0 | S8: =P8-$Q$4 -> 0 | T8: =Q8-$Q$4 -> 0 | U8: ='Conversion Deio2'!L7 -> 0 | V8: ='Conversion Deio2'!L8 -> 0 | W8: =AVERAGE(U8:V8) -> 0 | X8: =U8-$W$4 -> 0 | Y8: =V8-$W$4 -> 0 | Z8: =AVERAGE(W8-$W$4) -> 0 | AA8: ='Conversion Deio2'!M7 -> 0 | AB8: ='Conversion Deio2'!M8 -> 0 | AC8: =AVERAGE(AA8:AB8) -> 0 | AD8: =AA8-$AC$4 -> 0 | AE8: =AB8-$AC$4 -> 0 | AF8: =AC8-$AC$4 -> 0 | AG8: ='Conversion Deio2'!N7 -> 0 | AH8: ='Conversion Deio2'!N8 -> 0 | AI8: =AVERAGE(AG8:AH8) -> 0 | AJ8: =AG8-$AI$4 -> 0 | AK8: =AH8-$AI$4 -> 0 | AL8: =AI8-$AI$4 -> 0 | AM8: ='Conversion Deio2'!O7 -> 100 | AN8: ='Conversion Deio2'!O8 -> 100 | AO8: =AVERAGE(AM8:AN8) -> 100 | AP8: =AM8-$AO$4 -> 0 | AQ8: =AN8-$AO$4 -> 0 | AR8: =AO8-$AO$4 -> 0
H9: SD | K9: =_xlfn.STDEV.S(I8:J8) -> 0 | N9: =_xlfn.STDEV.S(L8:M8) -> 0 | Q9: =_xlfn.STDEV.S(O8:P8) -> 0 | T9: =_xlfn.STDEV.S(R8:S8) -> 0 | W9: =_xlfn.STDEV.S(U8:V8) -> 0 | Z9: =_xlfn.STDEV.S(X8:Y8) -> 0 | AF9: =_xlfn.STDEV.S(AD8:AE8) -> 0 | AL9: =_xlfn.STDEV.S(AJ8:AK8) -> 0 | AO9: =_xlfn.STDEV.S(AM8:AN8) -> 0 | AR9: =_xlfn.STDEV.S(AP8:AQ8) -> 0
A10: 3 | I10: ='Conversion Deio2'!J9 -> #DIV/0! | J10: ='Conversion Deio2'!J10 -> #DIV/0! | K10: =AVERAGE(I10:J10) -> #DIV/0! | L10: =I10-$K$4 -> #DIV/0! | M10: =J10-$K$4 -> #DIV/0! | N10: =K10-$K$4 -> #DIV/0! | O10: ='Conversion Deio2'!K9 -> #DIV/0! | P10: ='Conversion Deio2'!K10 -> #DIV/0! | Q10: 0 | R10: =O10-$Q$4 -> #DIV/0! | S10: =P10-$Q$4 -> #DIV/0! | T10: =Q10-$Q$4 -> 0 | U10: ='Conversion Deio2'!L9 -> #DIV/0! | V10: ='Conversion Deio2'!L10 -> #DIV/0! | W10: =AVERAGE(U10:V10) -> #DIV/0! | X10: =U10-$W$4 -> #DIV/0! | Y10: =V10-$W$4 -> #DIV/0! | Z10: =AVERAGE(W10-$W$4) -> #DIV/0! | AA10: ='Conversion Deio2'!M9 -> #DIV/0! | AB10: ='Conversion Deio2'!M10 -> #DIV/0! | AC10: =AVERAGE(AA10:AB10) -> #DIV/0! | AD10: =AA10-$AC$4 -> #DIV/0! | AE10: =AB10-$AC$4 -> #DIV/0! | AF10: =AC10-$AC$4 -> #DIV/0! | AG10: ='Conversion Deio2'!N9 -> #DIV/0! | AH10: ='Conversion Deio2'!N10 -> #DIV/0! | AI10: =AVERAGE(AG10:AH10) -> #DIV/0! | AJ10: =AG10-$AI$4 -> #DIV/0! | AK10: =AH10-$AI$4 -> #DIV/0! | AL10: =AI10-$AI$4 -> #DIV/0! | AM10: ='Conversion Deio2'!O9 -> #DIV/0! | AN10: ='Conversion Deio2'!O10 -> #DIV/0! | AO10: =AVERAGE(AM10:AN10) -> #DIV/0! | AP10: =AM10-$AO$4 -> #DIV/0! | AQ10: =AN10-$AO$4 -> #DIV/0! | AR10: =AO10-$AO$4 -> #DIV/0!
H11: SD | K11: =_xlfn.STDEV.S(I10:J10) -> #DIV/0! | N11: =_xlfn.STDEV.S(L10:M10) -> #DIV/0! | Q11: =_xlfn.STDEV.S(O10:P10) -> #DIV/0! | T11: =_xlfn.STDEV.S(R10:S10) -> #DIV/0! | W11: =_xlfn.STDEV.S(U10:V10) -> #DIV/0! | Z11: =_xlfn.STDEV.S(X10:Y10) -> #DIV/0! | AC11: =_xlfn.STDEV.S(AA10:AB10) -> #DIV/0! | AF11: =_xlfn.STDEV.S(AD10:AE10) -> #DIV/0! | AI11: =_xlfn.STDEV.S(AG10:AH10) -> #DIV/0! | AL11: =_xlfn.STDEV.S(AJ10:AK10) -> #DIV/0! | AO11: =_xlfn.STDEV.S(AM10:AN10) -> #DIV/0! | AR11: =_xlfn.STDEV.S(AP10:AQ10) -> #DIV/0!
A12: 4 | I12: ='Conversion Deio2'!J11 -> #DIV/0! | J12: ='Conversion Deio2'!J12 -> #DIV/0! | K12: =AVERAGE(I12:J12) -> #DIV/0! | L12: =I12-$K$4 -> #DIV/0! | M12: =J12-$K$4 -> #DIV/0! | N12: =K12-$K$4 -> #DIV/0! | O12: ='Conversion Deio2'!K11 -> #DIV/0! | P12: ='Conversion Deio2'!K12 -> #DIV/0! | Q12: =AVERAGE(O12:P12) -> #DIV/0! | R12: =O12-$Q$4 -> #DIV/0! | S12: =P12-$Q$4 -> #DIV/0! | T12: =AVERAGE(R12:S12) -> #DIV/0! | U12: ='Conversion Deio2'!L11 -> #DIV/0! | V12: ='Conversion Deio2'!L12 -> #DIV/0! | W12: =AVERAGE(U12:V12) -> #DIV/0! | X12: =U12-$W$4 -> #DIV/0! | Y12: =V12-$W$4 -> #DIV/0! | Z12: =AVERAGE(W12-$W$4) -> #DIV/0! | AA12: ='Conversion Deio2'!M11 -> #DIV/0! | AB12: ='Conversion Deio2'!M12 -> #DIV/0! | AC12: =AVERAGE(AA12:AB12) -> #DIV/0! | AD12: =AA12-$AC$4 -> #DIV/0! | AE12: =AB12-$AC$4 -> #DIV/0! | AF12: =AC12-$AC$4 -> #DIV/0! | AG12: ='Conversion Deio2'!N11 -> #DIV/0! | AH12: ='Conversion Deio2'!N12 -> #DIV/0! | AI12: =AVERAGE(AG12:AH12) -> #DIV/0! | AJ12: =AG12-$AI$4 -> #DIV/0! | AK12: =AH12-$AI$4 -> #DIV/0! | AL12: =AI12-$AI$4 -> #DIV/0! | AM12: ='Conversion Deio2'!O11 -> #DIV/0! | AN12: ='Conversion Deio2'!O12 -> #DIV/0! | AO12: =AVERAGE(AM12:AN12) -> #DIV/0! | AP12: =AM12-$AO$4 -> #DIV/0! | AQ12: =AN12-$AO$4 -> #DIV/0! | AR12: =AO12-$AO$4 -> #DIV/0!
H13: SD | K13: =_xlfn.STDEV.S(I12:J12) -> #DIV/0! | N13: =_xlfn.STDEV.S(L12:M12) -> #DIV/0! | Q13: =_xlfn.STDEV.S(O12:P12) -> #DIV/0! | T13: =_xlfn.STDEV.S(R12:S12) -> #DIV/0! | W13: =_xlfn.STDEV.S(U12:V12) -> #DIV/0! | Z13: =_xlfn.STDEV.S(X12:Y12) -> #DIV/0! | AC13: =_xlfn.STDEV.S(AA12:AB12) -> #DIV/0! | AF13: =_xlfn.STDEV.S(AD12:AE12) -> #DIV/0! | AI13: =_xlfn.STDEV.S(AG12:AH12) -> #DIV/0! | AL13: =_xlfn.STDEV.S(AJ12:AK12) -> #DIV/0! | AO13: =_xlfn.STDEV.S(AM12:AN12) -> #DIV/0! | AR13: =_xlfn.STDEV.S(AP12:AQ12) -> #DIV/0!
A14: 5 | I14: ='Conversion Deio2'!J13 -> #DIV/0! | J14: ='Conversion Deio2'!J14 -> #DIV/0! | K14: =AVERAGE(I14:J14) -> #DIV/0! | L14: =I14-$K$4 -> #DIV/0! | M14: =J14-$K$4 -> #DIV/0! | N14: =K14-$K$4 -> #DIV/0! | O14: ='Conversion Deio2'!K13 -> #DIV/0! | P14: ='Conversion Deio2'!K14 -> #DIV/0! | Q14: =AVERAGE(O14:P14) -> #DIV/0! | R14: =O14-$Q$4 -> #DIV/0! | S14: =P14-$Q$4 -> #DIV/0! | T14: =AVERAGE(R14:S14) -> #DIV/0! | U14: ='Conversion Deio2'!L13 -> #DIV/0! | V14: ='Conversion Deio2'!L14 -> #DIV/0! | W14: =AVERAGE(U14:V14) -> #DIV/0! | X14: =U14-$W$4 -> #DIV/0! | Y14: =V14-$W$4 -> #DIV/0! | Z14: =AVERAGE(W14-$W$4) -> #DIV/0! | AA14: ='Conversion Deio2'!M13 -> #DIV/0! | AB14: ='Conversion Deio2'!M14 -> #DIV/0! | AC14: =AVERAGE(AA14:AB14) -> #DIV/0! | AD14: =AA14-$AC$4 -> #DIV/0! | AE14: =AB14-$AC$4 -> #DIV/0! | AF14: =AC14-$AC$4 -> #DIV/0! | AG14: ='Conversion Deio2'!N13 -> #DIV/0! | AH14: ='Conversion Deio2'!N14 -> #DIV/0! | AI14: =AVERAGE(AG14:AH14) -> #DIV/0! | AJ14: =AG14-$AI$4 -> #DIV/0! | AK14: =AH14-$AI$4 -> #DIV/0! | AL14: =AI14-$AI$4 -> #DIV/0! | AM14: ='Conversion Deio2'!O13 -> #DIV/0! | AN14: ='Conversion Deio2'!O14 -> #DIV/0! | AO14: =AVERAGE(AM14:AN14) -> #DIV/0! | AP14: =AM14-$AO$4 -> #DIV/0! | AQ14: =AN14-$AO$4 -> #DIV/0! | AR14: =AO14-$AO$4 -> #DIV/0!
H15: SD | K15: =_xlfn.STDEV.S(I14:J14) -> #DIV/0! | N15: =_xlfn.STDEV.S(L14:M14) -> #DIV/0! | Q15: =_xlfn.STDEV.S(O14:P14) -> #DIV/0! | T15: =_xlfn.STDEV.S(R14:S14) -> #DIV/0! | W15: =_xlfn.STDEV.S(U14:V14) -> #DIV/0! | Z15: =_xlfn.STDEV.S(X14:Y14) -> #DIV/0! | AC15: =_xlfn.STDEV.S(AA14:AB14) -> #DIV/0! | AF15: =_xlfn.STDEV.S(AD14:AE14) -> #DIV/0! | AI15: =_xlfn.STDEV.S(AG14:AH14) -> #DIV/0! | AL15: =_xlfn.STDEV.S(AJ14:AK14) -> #DIV/0! | AO15: =_xlfn.STDEV.S(AM14:AN14) -> #DIV/0! | AR15: =_xlfn.STDEV.S(AP14:AQ14) -> #DIV/0!
A16: 6 | I16: ='Conversion Deio2'!J15 -> #DIV/0! | J16: ='Conversion Deio2'!J16 -> #DIV/0! | K16: =AVERAGE(I16:J16) -> #DIV/0! | L16: =I16-$K$4 -> #DIV/0! | M16: =J16-$K$4 -> #DIV/0! | N16: =K16-$K$4 -> #DIV/0! | O16: ='Conversion Deio2'!K15 -> #DIV/0! | P16: ='Conversion Deio2'!K16 -> #DIV/0! | Q16: =AVERAGE(O16:P16) -> #DIV/0! | R16: =O16-$Q$4 -> #DIV/0! | S16: =P16-$Q$4 -> #DIV/0! | T16: =AVERAGE(R16:S16) -> #DIV/0! | U16: ='Conversion Deio2'!L15 -> #DIV/0! | V16: ='Conversion Deio2'!L16 -> #DIV/0! | W16: =AVERAGE(U16:V16) -> #DIV/0! | X16: =U16-$W$4 -> #DIV/0! | Y16: =V16-$W$4 -> #DIV/0! | Z16: =AVERAGE(W16-$W$4) -> #DIV/0! | AA16: ='Conversion Deio2'!M15 -> #DIV/0! | AB16: ='Conversion Deio2'!M16 -> #DIV/0! | AC16: =AVERAGE(AA16:AB16) -> #DIV/0! | AD16: =AA16-$AC$4 -> #DIV/0! | AE16: =AB16-$AC$4 -> #DIV/0! | AF16: =AC16-$AC$4 -> #DIV/0! | AG16: ='Conversion Deio2'!N15 -> #DIV/0! | AH16: ='Conversion Deio2'!N16 -> #DIV/0! | AI16: =AVERAGE(AG16:AH16) -> #DIV/0! | AJ16: =AG16-$AI$4 -> #DIV/0! | AK16: =AH16-$AI$4 -> #DIV/0! | AL16: =AI16-$AI$4 -> #DIV/0! | AM16: ='Conversion Deio2'!O15 -> #DIV/0! | AN16: ='Conversion Deio2'!O16 -> #DIV/0! | AO16: =AVERAGE(AM16:AN16) -> #DIV/0! | AP16: =AM16-$AO$4 -> #DIV/0! | AQ16: =AN16-$AO$4 -> #DIV/0! | AR16: =AO16-$AO$4 -> #DIV/0!
H17: SD | K17: =_xlfn.STDEV.S(I16:J16) -> #DIV/0! | N17: =_xlfn.STDEV.S(L16:M16) -> #DIV/0! | Q17: =_xlfn.STDEV.S(O16:P16) -> #DIV/0! | T17: =_xlfn.STDEV.S(R16:S16) -> #DIV/0! | W17: =_xlfn.STDEV.S(U16:V16) -> #DIV/0! | Z17: =_xlfn.STDEV.S(X16:Y16) -> #DIV/0! | AC17: =_xlfn.STDEV.S(AA16:AB16) -> #DIV/0! | AF17: =_xlfn.STDEV.S(AD16:AE16) -> #DIV/0! | AI17: =_xlfn.STDEV.S(AG16:AH16) -> #DIV/0! | AL17: =_xlfn.STDEV.S(AJ16:AK16) -> #DIV/0! | AO17: =_xlfn.STDEV.S(AM16:AN16) -> #DIV/0! | AR17: =_xlfn.STDEV.S(AP16:AQ16) -> #DIV/0!
A18: 7 | I18: ='Conversion Deio2'!J17 -> #DIV/0! | J18: ='Conversion Deio2'!J18 -> #DIV/0! | K18: =AVERAGE(I18:J18) -> #DIV/0! | L18: =I18-$K$4 -> #DIV/0! | M18: =J18-$K$4 -> #DIV/0! | N18: =K18-$K$4 -> #DIV/0! | O18: ='Conversion Deio2'!K17 -> #DIV/0! | P18: ='Conversion Deio2'!K18 -> #DIV/0! | Q18: =AVERAGE(O18:P18) -> #DIV/0! | R18: =O18-$Q$4 -> #DIV/0! | S18: =P18-$Q$4 -> #DIV/0! | T18: =AVERAGE(R18:S18) -> #DIV/0! | U18: ='Conversion Deio2'!L17 -> #DIV/0! | V18: ='Conversion Deio2'!L18 -> #DIV/0! | W18: =AVERAGE(U18:V18) -> #DIV/0! | X18: =U18-$W$4 -> #DIV/0! | Y18: =V18-$W$4 -> #DIV/0! | Z18: =AVERAGE(W18-$W$4) -> #DIV/0! | AA18: ='Conversion Deio2'!M17 -> #DIV/0! | AB18: ='Conversion Deio2'!M18 -> #DIV/0! | AC18: =AVERAGE(AA18:AB18) -> #DIV/0! | AD18: =AA18-$AC$4 -> #DIV/0! | AE18: =AB18-$AC$4 -> #DIV/0! | AF18: =AC18-$AC$4 -> #DIV/0! | AG18: ='Conversion Deio2'!N17 -> #DIV/0! | AH18: ='Conversion Deio2'!N18 -> #DIV/0! | AI18: =AVERAGE(AG18:AH18) -> #DIV/0! | AJ18: =AG18-$AI$4 -> #DIV/0! | AK18: =AH18-$AI$4 -> #DIV/0! | AL18: =AI18-$AI$4 -> #DIV/0! | AM18: ='Conversion Deio2'!O17 -> #DIV/0! | AN18: ='Conversion Deio2'!O18 -> #DIV/0! | AO18: =AVERAGE(AM18:AN18) -> #DIV/0! | AP18: =AM18-$AO$4 -> #DIV/0! | AQ18: =AN18-$AO$4 -> #DIV/0! | AR18: =AO18-$AO$4 -> #DIV/0!
K19: =_xlfn.STDEV.S(I18:J18) -> #DIV/0! | N19: =_xlfn.STDEV.S(L18:M18) -> #DIV/0! | Q19: =_xlfn.STDEV.S(O18:P18) -> #DIV/0! | T19: =_xlfn.STDEV.S(R18:S18) -> #DIV/0! | W19: =_xlfn.STDEV.S(U18:V18) -> #DIV/0! | Z19: =_xlfn.STDEV.S(X18:Y18) -> #DIV/0! | AC19: =_xlfn.STDEV.S(AA18:AB18) -> #DIV/0! | AF19: =_xlfn.STDEV.S(AD18:AE18) -> #DIV/0! | AI19: =_xlfn.STDEV.S(AG18:AH18) -> #DIV/0! | AL19: =_xlfn.STDEV.S(AJ18:AK18) -> #DIV/0! | AO19: =_xlfn.STDEV.S(AM18:AN18) -> #DIV/0! | AR19: =_xlfn.STDEV.S(AP18:AQ18) -> #DIV/0!
A20: 8 | I20: ='Conversion Deio2'!J19 -> #DIV/0! | J20: ='Conversion Deio2'!J20 -> #DIV/0! | K20: =AVERAGE(I20:J20) -> #DIV/0! | L20: =I20-$K$4 -> #DIV/0! | M20: =J20-$K$4 -> #DIV/0! | N20: =K20-$K$4 -> #DIV/0! | O20: ='Conversion Deio2'!K19 -> #DIV/0! | P20: ='Conversion Deio2'!K20 -> #DIV/0! | Q20: =AVERAGE(O20:P20) -> #DIV/0! | R20: =O20-$Q$4 -> #DIV/0! | S20: =P20-$Q$4 -> #DIV/0! | T20: =AVERAGE(R20:S20) -> #DIV/0! | U20: ='Conversion Deio2'!L19 -> #DIV/0! | V20: ='Conversion Deio2'!L20 -> #DIV/0! | W20: =AVERAGE(U20:V20) -> #DIV/0! | X20: =U20-$W$4 -> #DIV/0! | Y20: =V20-$W$4 -> #DIV/0! | Z20: =AVERAGE(W20-$W$4) -> #DIV/0! | AA20: ='Conversion Deio2'!M19 -> #DIV/0! | AB20: ='Conversion Deio2'!M20 -> #DIV/0! | AC20: =AVERAGE(AA20:AB20) -> #DIV/0! | AD20: =AA20-$AC$4 -> #DIV/0! | AE20: =AB20-$AC$4 -> #DIV/0! | AF20: =AC20-$AC$4 -> #DIV/0! | AG20: ='Conversion Deio2'!N19 -> #DIV/0! | AH20: ='Conversion Deio2'!N20 -> #DIV/0! | AI20: =AVERAGE(AG20:AH20) -> #DIV/0! | AJ20: =AG20-$AI$4 -> #DIV/0! | AK20: =AH20-$AI$4 -> #DIV/0! | AL20: =AI20-$AI$4 -> #DIV/0! | AM20: ='Conversion Deio2'!O19 -> #DIV/0! | AN20: ='Conversion Deio2'!O20 -> #DIV/0! | AO20: =AVERAGE(AM20:AN20) -> #DIV/0! | AP20: =AM20-$AO$4 -> #DIV/0! | AQ20: =AN20-$AO$4 -> #DIV/0! | AR20: =AO20-$AO$4 -> #DIV/0!
K21: =_xlfn.STDEV.S(I20:J20) -> #DIV/0! | N21: =_xlfn.STDEV.S(L20:M20) -> #DIV/0! | Q21: =_xlfn.STDEV.S(O20:P20) -> #DIV/0! | T21: =_xlfn.STDEV.S(R20:S20) -> #DIV/0! | W21: =_xlfn.STDEV.S(U20:V20) -> #DIV/0! | Z21: =_xlfn.STDEV.S(X20:Y20) -> #DIV/0! | AC21: =_xlfn.STDEV.S(AA20:AB20) -> #DIV/0! | AF21: =_xlfn.STDEV.S(AD20:AE20) -> #DIV/0! | AI21: =_xlfn.STDEV.S(AG20:AH20) -> #DIV/0! | AL21: =_xlfn.STDEV.S(AJ20:AK20) -> #DIV/0! | AO21: =_xlfn.STDEV.S(AM20:AN20) -> #DIV/0! | AR21: =_xlfn.STDEV.S(AP20:AQ20) -> #DIV/0!
C26: D2 (%T3 net) A | D26: D2 (%T3 net) B | E26: fmol/min/mg A | F26: fmol/min/mg B | H26: fmol/min/mg average | J26: SD
T27: Formula
B28: SKNAS 1 | C28: =AD6 -> 0 | D28: =AE6 -> 0 | E28: =C28/$AO$4*2000/120/F6 -> 0 | F28: =D28/$AO$4*2000/120/F6 -> 0 | H28: =AVERAGE(E28:F28) -> 0 | J28: =_xlfn.STDEV.S(E28:F28) -> 0
C29: =AD8 -> 0 | D29: =AE8 -> 0 | E29: =C29/$AO$4*2000/120/F8 -> 0 | F29: =D29/$AO$4*2000/120/F8 -> 0 | H29: =AVERAGE(E29:F29) -> 0 | J29: =_xlfn.STDEV.S(E29:F29) -> 0
C30: =AD10 -> #DIV/0! | D30: =AE10 -> #DIV/0! | E30: =C30/$AO$4*2000/120/F10 -> #DIV/0! | F30: =D30/$AO$4*2000/120/F10 -> #DIV/0! | H30: =AVERAGE(E30:F30) -> #DIV/0! | J30: =_xlfn.STDEV.S(E30:F30) -> #DIV/0!
C31: =AD12 -> #DIV/0! | D31: =AE12 -> #DIV/0! | E31: =C31/$AO$4*2000/120/F12 -> #DIV/0! | F31: =D31/$AO$4*2000/120/F12 -> #DIV/0! | H31: =AVERAGE(E31:F31) -> #DIV/0! | J31: =_xlfn.STDEV.S(E31:F31) -> #DIV/0! | T31: We add 1 nM of cold T3 | W31: 1 nM = 10^6 fmol/L
C32: =AD14 -> #DIV/0! | D32: =AE14 -> #DIV/0! | E32: =C32/$AO$4*2000/120/F14 -> #DIV/0! | F32: =D32/$AO$4*2000/120/F14 -> #DIV/0! | H32: =AVERAGE(E32:F32) -> #DIV/0! | J32: =_xlfn.STDEV.S(E32:F32) -> #DIV/0!
C33: =AD16 -> #DIV/0! | D33: =AE16 -> #DIV/0! | E33: =C33/$AO$4*2000/120/F16 -> #DIV/0! | F33: =D33/$AO$4*2000/120/F16 -> #DIV/0! | H33: =AVERAGE(E33:F33) -> #DIV/0! | J33: =_xlfn.STDEV.S(E33:F33) -> #DIV/0!
C34: =AD18 -> #DIV/0! | D34: =AE18 -> #DIV/0! | E34: =C34/$AO$4*2000/120/F18 -> #DIV/0! | F34: =D34/$AO$4*2000/120/F18 -> #DIV/0! | H34: =AVERAGE(E34:F34) -> #DIV/0! | J34: =_xlfn.STDEV.S(E34:F34) -> #DIV/0!
C35: =AD20 -> #DIV/0! | D35: =AE20 -> #DIV/0! | E35: =C35/$AO$4*2000/120/F20 -> #DIV/0! | F35: =D35/$AO$4*2000/120/F20 -> #DIV/0! | H35: =AVERAGE(E35:F35) -> #DIV/0! | J35: =_xlfn.STDEV.S(E35:F35) -> #DIV/0!

Sheet Conversion Deio3
A1: 08/06/2021 NPC WTC1c
A2: Name | B2: I (1.3) | C2: T1 (2.9) | D2: 3,3'-T2 (5.7) | E2: T3 (8.1) | F2: rT3 (8.9) | G2: T4 (11.5) | H2: Som | J2: %I | K2: %T1 | L2: %T2 | M2: %T3 | N2: %rT3 | O2: %T4
A3: T3 Tracer A | B3: =157043+231396 -> 388439 | E3: 5417680 | H3: =SUM(B3:G3) -> 5806119 | J3: =(B3/H3)*100 -> 6.690166 | K3: =(C3/H3)*100 -> 0 | L3: =(D3/H3)*100 -> 0 | M3: =(E3/H3)*100 -> 93.309834 | N3: =(F3/H3)*100 -> 0 | O3: =(G3/H3)*100 -> 0
A4: T3 Tracer B | B4: 402417 | E4: 4995309 | H4: =SUM(B4:G4) -> 5397726 | J4: =(B4/H4)*100 -> 7.4553062 | K4: =(C4/H4)*100 -> 0 | L4: =(D4/H4)*100 -> 0 | M4: =(E4/H4)*100 -> 92.544694 | N4: =(F4/H4)*100 -> 0 | O4: =(G4/H4)*100 -> 0
A5: SK 1-1 | B5: 310568 | D5: 278823 | E5: 4546678 | H5: =SUM(B5:G5) -> 5136069 | J5: =(B5/H5)*100 -> 6.0468035 | K5: =(C5/H5)*100 -> 0 | L5: =(D5/H5)*100 -> 5.4287238 | M5: =(E5/H5)*100 -> 88.524473 | N5: =(F5/H5)*100 -> 0 | O5: =(G5/H5)*100 -> 0
A6: SK1-2 | B6: 256544 | D6: 170434 | E6: 5310401 | H6: =SUM(B6:G6) -> 5737379 | J6: =(B6/H6)*100 -> 4.4714494 | K6: =(C6/H6)*100 -> 0 | L6: =(D6/H6)*100 -> 2.9705899 | M6: =(E6/H6)*100 -> 92.557961 | N6: =(F6/H6)*100 -> 0 | O6: =(G6/H6)*100 -> 0
A7: SK 2-1 | B7: 297044 | D7: =225892+65408+18434 -> 309734 | E7: 4825645 | H7: =SUM(B7:G7) -> 5432423 | J7: =(B7/H7)*100 -> 5.4679836 | K7: =(C7/H7)*100 -> 0 | L7: =(D7/H7)*100 -> 5.701581 | M7: =(E7/H7)*100 -> 88.830435 | N7: =(F7/H7)*100 -> 0 | O7: =(G7/H7)*100 -> 0
A8: SK 2-2 | B8: =121457+98278+139439 -> 359174 | D8: =256118+236472 -> 492590 | E8: 4482685 | H8: =SUM(B8:G8) -> 5334449 | J8: =(B8/H8)*100 -> 6.733104 | K8: =(C8/H8)*100 -> 0 | L8: =(D8/H8)*100 -> 9.2341308 | M8: =(E8/H8)*100 -> 84.032765 | N8: =(F8/H8)*100 -> 0 | O8: =(G8/H8)*100 -> 0 | AB8: ='Conversion Deio3'!M8\ -> #NAME?
H9: =SUM(B9:G9) -> 0 | J9: =(B9/H9)*100 -> #DIV/0! | K9: =(C9/H9)*100 -> #DIV/0! | L9: =(D9/H9)*100 -> #DIV/0! | M9: =(E9/H9)*100 -> #DIV/0! | N9: =(F9/H9)*100 -> #DIV/0! | O9: =(G9/H9)*100 -> #DIV/0!
H10: =SUM(B10:G10) -> 0 | J10: =(B10/H10)*100 -> #DIV/0! | K10: =(C10/H10)*100 -> #DIV/0! | L10: =(D10/H10)*100 -> #DIV/0! | M10: =(E10/H10)*100 -> #DIV/0! | N10: =(F10/H10)*100 -> #DIV/0! | O10: =(G10/H10)*100 -> #DIV/0!
H11: =SUM(B11:G11) -> 0 | J11: =(B11/H11)*100 -> #DIV/0! | K11: =(C11/H11)*100 -> #DIV/0! | L11: =(D11/H11)*100 -> #DIV/0! | M11: =(E11/H11)*100 -> #DIV/0! | N11: =(F11/H11)*100 -> #DIV/0! | O11: =(G11/H11)*100 -> #DIV/0!
H12: =SUM(B12:G12) -> 0 | J12: =(B12/H12)*100 -> #DIV/0! | K12: =(C12/H12)*100 -> #DIV/0! | L12: =(D12/H12)*100 -> #DIV/0! | M12: =(E12/H12)*100 -> #DIV/0! | N12: =(F12/H12)*100 -> #DIV/0! | O12: =(G12/H12)*100 -> #DIV/0!
H13: =SUM(B13:G13) -> 0 | J13: =(B13/H13)*100 -> #DIV/0! | K13: =(C13/H13)*100 -> #DIV/0! | L13: =(D13/H13)*100 -> #DIV/0! | M13: =(E13/H13)*100 -> #DIV/0! | N13: =(F13/H13)*100 -> #DIV/0! | O13: =(G13/H13)*100 -> #DIV/0!
H14: =SUM(B14:G14) -> 0 | J14: =(B14/H14)*100 -> #DIV/0! | K14: =(C14/H14)*100 -> #DIV/0! | L14: =(D14/H14)*100 -> #DIV/0! | M14: =(E14/H14)*100 -> #DIV/0! | N14: =(F14/H14)*100 -> #DIV/0! | O14: =(G14/H14)*100 -> #DIV/0!
H15: =SUM(B15:G15) -> 0 | J15: =(B15/H15)*100 -> #DIV/0! | K15: =(C15/H15)*100 -> #DIV/0! | L15: =(D15/H15)*100 -> #DIV/0! | M15: =(E15/H15)*100 -> #DIV/0! | N15: =(F15/H15)*100 -> #DIV/0! | O15: =(G15/H15)*100 -> #DIV/0!
H16: =SUM(B16:G16) -> 0 | J16: =(B16/H16)*100 -> #DIV/0! | K16: =(C16/H16)*100 -> #DIV/0! | L16: =(D16/H16)*100 -> #DIV/0! | M16: =(E16/H16)*100 -> #DIV/0! | N16: =(F16/H16)*100 -> #DIV/0! | O16: =(G16/H16)*100 -> #DIV/0!
H17: =SUM(B17:G17) -> 0 | J17: =(B17/H17)*100 -> #DIV/0! | K17: =(C17/H17)*100 -> #DIV/0! | L17: =(D17/H17)*100 -> #DIV/0! | M17: =(E17/H17)*100 -> #DIV/0! | N17: =(F17/H17)*100 -> #DIV/0! | O17: =(G17/H17)*100 -> #DIV/0!
H18: =SUM(B18:G18) -> 0 | J18: =(B18/H18)*100 -> #DIV/0! | K18: =(C18/H18)*100 -> #DIV/0! | L18: =(D18/H18)*100 -> #DIV/0! | M18: =(E18/H18)*100 -> #DIV/0! | N18: =(F18/H18)*100 -> #DIV/0! | O18: =(G18/H18)*100 -> #DIV/0!
H19: =SUM(B19:G19) -> 0 | J19: =(B19/H19)*100 -> #DIV/0! | K19: =(C19/H19)*100 -> #DIV/0! | L19: =(D19/H19)*100 -> #DIV/0! | M19: =(E19/H19)*100 -> #DIV/0! | N19: =(F19/H19)*100 -> #DIV/0! | O19: =(G19/H19)*100 -> #DIV/0!
H20: =SUM(B20:G20) -> 0 | J20: =(B20/H20)*100 -> #DIV/0! | K20: =(C20/H20)*100 -> #DIV/0! | L20: =(D20/H20)*100 -> #DIV/0! | M20: =(E20/H20)*100 -> #DIV/0! | N20: =(F20/H20)*100 -> #DIV/0! | O20: =(G20/H20)*100 -> #DIV/0!

Sheet Analysis D3
A2: sample | C2: Time incubation (min) | D2: dilution | E2: protein concentration mg/ml | I2: %Ia | J2: %Ib | K2: %Iav | L2: %Inet A | M2: %Inet B | N2: %Inet avg | O2: %T1a | P2: %T1b | Q2: %T1av | R2: %T1net A | S2: %T1net B | T2: %T1net avg | U2: %T2a | V2: %T2b | W2: %T2av | X2: %T2net A | Y2: %T2net B | Z2: %T2net avg | AA2: %T3a | AB2: %T3b | AC2: %T3av | AD2: %T3net A | AE2: %T3net B | AF2: %T3net avg | AG2: %rT3a | AH2: %rT3b | AI2: %rT3av | AJ2: %rT3net A | AK2: %rT3net B | AL2: %rT3net avg | AM2: %T4a | AN2: %T4b | AO2: %T4av | AP2: %T4net A | AQ2: %T4net B | AR2: %T4net avg
B4: Tracer | I4: ='Conversion Deio3'!J3 -> 6.690166 | J4: ='Conversion Deio3'!J4 -> 7.4553062 | K4: =AVERAGE(I4) -> 6.690166 | O4: ='Conversion Deio3'!K3 -> 0 | P4: ='Conversion Deio3'!K4 -> 0 | Q4: =AVERAGE(O4:P4) -> 0 | U4: ='Conversion Deio3'!L3 -> 0 | V4: ='Conversion Deio3'!L4 -> 0 | W4: =AVERAGE(U4) -> 0 | AA4: ='Conversion Deio3'!M3 -> 93.309834 | AB4: ='Conversion Deio3'!M4 -> 92.544694 | AC4: =AVERAGE(AA4) -> 93.309834 | AG4: ='Conversion Deio3'!N3 -> 0 | AH4: ='Conversion Deio3'!N4 -> 0 | AI4: =AVERAGE(AG4:AH4) -> 0 | AM4: ='Conversion Deio3'!O3 -> 0 | AN4: ='Conversion Deio3'!O4 -> 0 | AO4: =AVERAGE(AM4:AN4) -> 0
H5: SD | K5: =_xlfn.STDEV.S(I4:J4) -> 0.5410358
A6: 1 | B6: SKNAS 1 | C6: 120 | F6: ='Protein concentration'!E32 -> 0.55505891 | I6: ='Conversion Deio3'!J5 -> 6.0468035 | J6: ='Conversion Deio3'!J6 -> 4.4714494 | K6: =AVERAGE(I6:J6) -> 5.2591265 | L6: =I6-$K$4 -> -0.64336251 | M6: =J6-$K$4 -> -2.2187166 | N6: =K6-$K$4 -> -1.4310396 | O6: ='Conversion Deio3'!K5 -> 0 | P6: ='Conversion Deio3'!K6 -> 0 | Q6: =AVERAGE(O6:P6) -> 0 | R6: =O6-$Q$4 -> 0 | S6: =P6-$Q$4 -> 0 | T6: =Q6-$Q$4 -> 0 | U6: ='Conversion Deio3'!L5 -> 5.4287238 | V6: ='Conversion Deio3'!L6 -> 2.9705899 | W6: =AVERAGE(U6:V6) -> 4.1996568 | X6: =U6-$W$4 -> 5.4287238 | Y6: =V6-$W$4 -> 2.9705899 | Z6: =AVERAGE(W6-$W$4) -> 4.1996568 | AA6: ='Conversion Deio3'!M5 -> 88.524473 | AB6: ='Conversion Deio3'!M6 -> 92.557961 | AC6: =AVERAGE(AA6:AB6) -> 90.541217 | AD6: =AA6-$AC$4 -> -4.7853613 | AE6: =AB6-$AC$4 -> -0.75187329 | AF6: =AC6-$AC$4 -> -2.7686173 | AG6: ='Conversion Deio2'!N5 -> 0 | AH6: ='Conversion Deio2'!N6 -> 0 | AI6: =AVERAGE(AG6:AH6) -> 0 | AJ6: =AG6-$AI$4 -> 0 | AK6: =AH6-$AI$4 -> 0 | AL6: =AI6-$AI$4 -> 0 | AM6: =#REF! -> #REF! | AN6: 0 | AO6: =AVERAGE(AM6:AN6) -> #REF! | AP6: =AM6-$AO$4 -> #REF! | AQ6: =AN6-$AO$4 -> 0 | AR6: =AO6-$AO$4 -> #REF!
H7: SD | K7: =_xlfn.STDEV.S(I6:J6) -> 1.1139436 | N7: =_xlfn.STDEV.S(L6:M6) -> 1.1139436 | Q7: =_xlfn.STDEV.S(O6:P6) -> 0 | T7: =_xlfn.STDEV.S(R6:S6) -> 0 | W7: =_xlfn.STDEV.S(U6:V6) -> 1.7381632 | Z7: =_xlfn.STDEV.S(X6:Y6) -> 1.7381632 | AC7: =_xlfn.STDEV.S(AA6:AB6) -> 2.8521067 | AF7: =_xlfn.STDEV.S(AD6:AE6) -> 2.8521067 | AO7: =_xlfn.STDEV.S(AM6:AN6) -> #REF! | AR7: =_xlfn.STDEV.S(AP6:AQ6) -> #REF!
A8: 2 | B8: SKNAS 2 | C8: 120 | F8: ='Protein concentration'!E33 -> 0.55149947 | I8: ='Conversion Deio3'!J7 -> 5.4679836 | J8: ='Conversion Deio3'!J8 -> 6.733104 | K8: =AVERAGE(I8:J8) -> 6.1005438 | L8: =I8-$K$4 -> -1.2221824 | M8: =J8-$K$4 -> 0.042938006 | N8: =K8-$K$4 -> -0.58962219 | O8: ='Conversion Deio3'!K7 -> 0 | P8: ='Conversion Deio3'!K8 -> 0 | Q8: =AVERAGE(O8:P8) -> 0 | R8: =O8-$Q$4 -> 0 | S8: =P8-$Q$4 -> 0 | T8: =Q8-$Q$4 -> 0 | U8: ='Conversion Deio3'!L7 -> 5.701581 | V8: ='Conversion Deio3'!L8 -> 9.2341308 | W8: =AVERAGE(U8:V8) -> 7.4678559 | X8: =U8-$W$4 -> 5.701581 | Y8: =V8-$W$4 -> 9.2341308 | Z8: =AVERAGE(W8-$W$4) -> 7.4678559 | AA8: ='Conversion Deio3'!M7 -> 88.830435 | AB8: ='Conversion Deio3'!M8 -> 84.032765 | AC8: =AVERAGE(AA8:AB8) -> 86.4316 | AD8: =AA8-$AC$4 -> -4.4793987 | AE8: =AB8-$AC$4 -> -9.2770688 | AF8: =AC8-$AC$4 -> -6.8782337 | AG8: =#REF! -> #REF! | AH8: =#REF! -> #REF! | AI8: =AVERAGE(AG8:AH8) -> #REF! | AJ8: =AG8-$AI$4 -> #REF! | AK8: =AH8-$AI$4 -> #REF! | AL8: =AI8-$AI$4 -> #REF! | AM8: =#REF! -> #REF! | AN8: =#REF! -> #REF! | AO8: =AVERAGE(AM8:AN8) -> #REF! | AP8: =AM8-$AO$4 -> #REF! | AQ8: =AN8-$AO$4 -> #REF!
H9: SD | K9: =_xlfn.STDEV.S(I8:J8) -> 0.89457521 | N9: =_xlfn.STDEV.S(L8:M8) -> 0.89457521 | Q9: =_xlfn.STDEV.S(O8:P8) -> 0 | T9: =_xlfn.STDEV.S(R8:S8) -> 0 | W9: =_xlfn.STDEV.S(U8:V8) -> 2.4978899 | Z9: =_xlfn.STDEV.S(X8:Y8) -> 2.4978899 | AF9: =_xlfn.STDEV.S(AD8:AE8) -> 3.3924651
A10: 3 | I10: ='Conversion Deio3'!J9 -> #DIV/0! | J10: ='Conversion Deio2'!J10 -> #DIV/0! | K10: =AVERAGE(I10:J10) -> #DIV/0! | L10: =I10-$K$4 -> #DIV/0! | M10: =J10-$K$4 -> #DIV/0! | N10: =K10-$K$4 -> #DIV/0! | O10: ='Conversion Deio3'!K9 -> #DIV/0! | P10: ='Conversion Deio3'!K10 -> #DIV/0! | Q10: 0 | R10: =O10-$Q$4 -> #DIV/0! | S10: =P10-$Q$4 -> #DIV/0! | T10: =Q10-$Q$4 -> 0 | U10: ='Conversion Deio3'!L9 -> #DIV/0! | V10: ='Conversion Deio3'!L10 -> #DIV/0! | W10: =AVERAGE(U10:V10) -> #DIV/0! | X10: =U10-$W$4 -> #DIV/0! | Y10: =V10-$W$4 -> #DIV/0! | Z10: =AVERAGE(W10-$W$4) -> #DIV/0! | AA10: ='Conversion Deio3'!M9 -> #DIV/0! | AB10: ='Conversion Deio3'!M10 -> #DIV/0! | AC10: =AVERAGE(AA10:AB10) -> #DIV/0! | AD10: =AA10-$AC$4 -> #DIV/0! | AE10: =AB10-$AC$4 -> #DIV/0! | AF10: =AC10-$AC$4 -> #DIV/0! | AG10: 0 | AH10: 0 | AI10: 0 | AJ10: =AG10-$AI$4 -> 0 | AK10: =AH10-$AI$4 -> 0 | AL10: =AI10-$AI$4 -> 0 | AM10: 0 | AN10: 0 | AO10: =AVERAGE(AM10:AN10) -> 0 | AP10: =AM10-$AO$4 -> 0 | AQ10: =AN10-$AO$4 -> 0 | AR10: =AO10-$AO$4 -> 0
H11: SD | K11: =_xlfn.STDEV.S(I10:J10) -> #DIV/0! | N11: =_xlfn.STDEV.S(L10:M10) -> #DIV/0! | Q11: =_xlfn.STDEV.S(O10:P10) -> #DIV/0! | T11: =_xlfn.STDEV.S(R10:S10) -> #DIV/0! | W11: =_xlfn.STDEV.S(U10:V10) -> #DIV/0! | Z11: =_xlfn.STDEV.S(X10:Y10) -> #DIV/0! | AC11: =_xlfn.STDEV.S(AA10:AB10) -> #DIV/0! | AF11: =_xlfn.STDEV.S(AD10:AE10) -> #DIV/0! | AO11: =_xlfn.STDEV.S(AM10:AN10) -> 0 | AR11: =_xlfn.STDEV.S(AP10:AQ10) -> 0
A12: 4 | I12: ='Conversion Deio3'!J11 -> #DIV/0! | J12: ='Conversion Deio2'!J12 -> #DIV/0! | K12: =AVERAGE(I12:J12) -> #DIV/0! | L12: =I12-$K$4 -> #DIV/0! | M12: =J12-$K$4 -> #DIV/0! | N12: =K12-$K$4 -> #DIV/0! | O12: ='Conversion Deio3'!K11 -> #DIV/0! | P12: ='Conversion Deio3'!K12 -> #DIV/0! | Q12: =AVERAGE(O12:P12) -> #DIV/0! | R12: =O12-$Q$4 -> #DIV/0! | S12: =P12-$Q$4 -> #DIV/0! | T12: =AVERAGE(R12:S12) -> #DIV/0! | U12: ='Conversion Deio3'!L11 -> #DIV/0! | V12: ='Conversion Deio3'!L12 -> #DIV/0! | W12: =AVERAGE(U12:V12) -> #DIV/0! | X12: =U12-$W$4 -> #DIV/0! | Y12: =V12-$W$4 -> #DIV/0! | Z12: =AVERAGE(W12-$W$4) -> #DIV/0! | AA12: ='Conversion Deio3'!M11 -> #DIV/0! | AB12: ='Conversion Deio3'!M12 -> #DIV/0! | AC12: =AVERAGE(AA12:AB12) -> #DIV/0! | AD12: =AA12-$AC$4 -> #DIV/0! | AE12: =AB12-$AC$4 -> #DIV/0! | AF12: =AC12-$AC$4 -> #DIV/0! | AG12: =#REF! -> #REF! | AH12: =#REF! -> #REF! | AI12: 0 | AJ12: =AG12-$AI$4 -> #REF! | AK12: =AH12-$AI$4 -> #REF! | AL12: =AI12-$AI$4 -> 0 | AM12: =#REF! -> #REF! | AN12: =#REF! -> #REF! | AO12: =AVERAGE(AM12:AN12) -> #REF! | AP12: =AM12-$AO$4 -> #REF! | AQ12: =AN12-$AO$4 -> #REF! | AR12: =AO12-$AO$4 -> #REF!
H13: SD | K13: =_xlfn.STDEV.S(I12:J12) -> #DIV/0! | N13: =_xlfn.STDEV.S(L12:M12) -> #DIV/0! | Q13: =_xlfn.STDEV.S(O12:P12) -> #DIV/0! | T13: =_xlfn.STDEV.S(R12:S12) -> #DIV/0! | W13: =_xlfn.STDEV.S(U12:V12) -> #DIV/0! | Z13: =_xlfn.STDEV.S(X12:Y12) -> #DIV/0! | AC13: =_xlfn.STDEV.S(AA12:AB12) -> #DIV/0! | AF13: =_xlfn.STDEV.S(AD12:AE12) -> #DIV/0!
A14: 5 | I14: ='Conversion Deio3'!J13 -> #DIV/0! | J14: ='Conversion Deio2'!J14 -> #DIV/0! | K14: =AVERAGE(I14:J14) -> #DIV/0! | L14: =I14-$K$4 -> #DIV/0! | M14: =J14-$K$4 -> #DIV/0! | N14: =K14-$K$4 -> #DIV/0! | O14: ='Conversion Deio3'!K13 -> #DIV/0! | P14: ='Conversion Deio3'!K14 -> #DIV/0! | Q14: =AVERAGE(O14:P14) -> #DIV/0! | R14: =O14-$Q$4 -> #DIV/0! | S14: =P14-$Q$4 -> #DIV/0! | T14: =AVERAGE(R14:S14) -> #DIV/0! | U14: ='Conversion Deio3'!L13 -> #DIV/0! | V14: ='Conversion Deio3'!L14 -> #DIV/0! | W14: =AVERAGE(U14:V14) -> #DIV/0! | X14: =U14-$W$4 -> #DIV/0! | Y14: =V14-$W$4 -> #DIV/0! | Z14: =AVERAGE(W14-$W$4) -> #DIV/0! | AA14: ='Conversion Deio3'!M13 -> #DIV/0! | AB14: ='Conversion Deio3'!M14 -> #DIV/0! | AC14: =AVERAGE(AA14:AB14) -> #DIV/0! | AD14: =AA14-$AC$4 -> #DIV/0! | AE14: =AB14-$AC$4 -> #DIV/0! | AF14: =AC14-$AC$4 -> #DIV/0! | AG14: =#REF! -> #REF! | AH14: =#REF! -> #REF! | AI14: 0 | AJ14: =AG14-$AI$4 -> #REF! | AK14: =AH14-$AI$4 -> #REF! | AL14: =AI14-$AI$4 -> 0 | AM14: =#REF! -> #REF! | AN14: =#REF! -> #REF! | AO14: =AVERAGE(AM14:AN14) -> #REF! | AP14: =AM14-$AO$4 -> #REF! | AQ14: =AN14-$AO$4 -> #REF! | AR14: =AO14-$AO$4 -> #REF!
H15: SD | K15: =_xlfn.STDEV.S(I14:J14) -> #DIV/0! | N15: =_xlfn.STDEV.S(L14:M14) -> #DIV/0! | Q15: =_xlfn.STDEV.S(O14:P14) -> #DIV/0! | T15: =_xlfn.STDEV.S(R14:S14) -> #DIV/0! | W15: =_xlfn.STDEV.S(U14:V14) -> #DIV/0! | Z15: =_xlfn.STDEV.S(X14:Y14) -> #DIV/0! | AC15: =_xlfn.STDEV.S(AA14:AB14) -> #DIV/0! | AF15: =_xlfn.STDEV.S(AD14:AE14) -> #DIV/0!
A16: 6 | I16: ='Conversion Deio3'!J15 -> #DIV/0! | J16: ='Conversion Deio3'!J16 -> #DIV/0! | K16: =AVERAGE(I16:J16) -> #DIV/0! | L16: =I16-$K$4 -> #DIV/0! | M16: =J16-$K$4 -> #DIV/0! | N16: =K16-$K$4 -> #DIV/0! | O16: ='Conversion Deio3'!K15 -> #DIV/0! | P16: ='Conversion Deio3'!K16 -> #DIV/0! | Q16: =AVERAGE(O16:P16) -> #DIV/0! | R16: =O16-$Q$4 -> #DIV/0! | S16: =P16-$Q$4 -> #DIV/0! | T16: =AVERAGE(R16:S16) -> #DIV/0! | U16: ='Conversion Deio3'!L15 -> #DIV/0! | V16: ='Conversion Deio3'!L16 -> #DIV/0! | W16: =AVERAGE(U16:V16) -> #DIV/0! | X16: =U16-$W$4 -> #DIV/0! | Y16: =V16-$W$4 -> #DIV/0! | Z16: =AVERAGE(W16-$W$4) -> #DIV/0! | AA16: ='Conversion Deio3'!M15 -> #DIV/0! | AB16: ='Conversion Deio3'!M16 -> #DIV/0! | AC16: =AVERAGE(AA16:AB16) -> #DIV/0! | AD16: =AA16-$AC$4 -> #DIV/0! | AE16: =AB16-$AC$4 -> #DIV/0! | AF16: =AC16-$AC$4 -> #DIV/0! | AG16: =#REF! -> #REF! | AH16: =#REF! -> #REF! | AI16: 0 | AJ16: =AG16-$AI$4 -> #REF! | AK16: =AH16-$AI$4 -> #REF! | AL16: =AI16-$AI$4 -> 0 | AM16: =#REF! -> #REF! | AN16: =#REF! -> #REF! | AO16: =AVERAGE(AM16:AN16) -> #REF! | AP16: =AM16-$AO$4 -> #REF! | AQ16: =AN16-$AO$4 -> #REF! | AR16: =AO16-$AO$4 -> #REF!
H17: SD | K17: =_xlfn.STDEV.S(I16:J16) -> #DIV/0! | N17: =_xlfn.STDEV.S(L16:M16) -> #DIV/0! | Q17: =_xlfn.STDEV.S(O16:P16) -> #DIV/0! | T17: =_xlfn.STDEV.S(R16:S16) -> #DIV/0! | W17: =_xlfn.STDEV.S(U16:V16) -> #DIV/0! | Z17: =_xlfn.STDEV.S(X16:Y16) -> #DIV/0! | AC17: =_xlfn.STDEV.S(AA16:AB16) -> #DIV/0! | AF17: =_xlfn.STDEV.S(AD16:AE16) -> #DIV/0!
A18: 7 | I18: ='Conversion Deio3'!J17 -> #DIV/0! | J18: ='Conversion Deio3'!J18 -> #DIV/0! | K18: =AVERAGE(I18:J18) -> #DIV/0! | L18: =I18-$K$4 -> #DIV/0! | M18: =J18-$K$4 -> #DIV/0! | N18: =K18-$K$4 -> #DIV/0! | O18: ='Conversion Deio3'!K17 -> #DIV/0! | P18: ='Conversion Deio3'!K18 -> #DIV/0! | Q18: =AVERAGE(O18:P18) -> #DIV/0! | R18: =O18-$Q$4 -> #DIV/0! | S18: =P18-$Q$4 -> #DIV/0! | T18: =AVERAGE(R18:S18) -> #DIV/0! | U18: ='Conversion Deio3'!L17 -> #DIV/0! | V18: ='Conversion Deio3'!L18 -> #DIV/0! | W18: =AVERAGE(U18:V18) -> #DIV/0! | X18: =U18-$W$4 -> #DIV/0! | Y18: =V18-$W$4 -> #DIV/0! | Z18: =AVERAGE(W18-$W$4) -> #DIV/0! | AA18: ='Conversion Deio3'!M17 -> #DIV/0! | AB18: ='Conversion Deio3'!M18 -> #DIV/0! | AC18: =AVERAGE(AA18:AB18) -> #DIV/0! | AD18: =AA18-$AC$4 -> #DIV/0! | AE18: =AB18-$AC$4 -> #DIV/0! | AF18: =AC18-$AC$4 -> #DIV/0! | AG18: =#REF! -> #REF! | AH18: =#REF! -> #REF! | AI18: 0 | AJ18: =AG18-$AI$4 -> #REF! | AK18: =AH18-$AI$4 -> #REF! | AL18: =AI18-$AI$4 -> 0 | AM18: =#REF! -> #REF! | AN18: =#REF! -> #REF! | AO18: =AVERAGE(AM18:AN18) -> #REF! | AP18: =AM18-$AO$4 -> #REF! | AQ18: =AN18-$AO$4 -> #REF! | AR18: =AO18-$AO$4 -> #REF!
H19: SD | K19: =_xlfn.STDEV.S(I18:J18) -> #DIV/0! | N19: =_xlfn.STDEV.S(L18:M18) -> #DIV/0! | Q19: =_xlfn.STDEV.S(O18:P18) -> #DIV/0! | T19: =_xlfn.STDEV.S(R18:S18) -> #DIV/0! | W19: =_xlfn.STDEV.S(U18:V18) -> #DIV/0! | Z19: =_xlfn.STDEV.S(X18:Y18) -> #DIV/0! | AC19: =_xlfn.STDEV.S(AA18:AB18) -> #DIV/0! | AF19: =_xlfn.STDEV.S(AD18:AE18) -> #DIV/0!
A20: 8 | I20: ='Conversion Deio3'!J19 -> #DIV/0! | J20: ='Conversion Deio3'!J20 -> #DIV/0! | K20: =AVERAGE(I20:J20) -> #DIV/0! | L20: =I20-$K$4 -> #DIV/0! | M20: =J20-$K$4 -> #DIV/0! | N20: =K20-$K$4 -> #DIV/0! | O20: ='Conversion Deio3'!K19 -> #DIV/0! | P20: ='Conversion Deio3'!K20 -> #DIV/0! | Q20: =AVERAGE(O20:P20) -> #DIV/0! | R20: =O20-$Q$4 -> #DIV/0! | S20: =P20-$Q$4 -> #DIV/0! | T20: =AVERAGE(R20:S20) -> #DIV/0! | U20: ='Conversion Deio3'!L19 -> #DIV/0! | V20: ='Conversion Deio3'!L20 -> #DIV/0! | W20: =AVERAGE(U20:V20) -> #DIV/0! | X20: =U20-$W$4 -> #DIV/0! | Y20: =V20-$W$4 -> #DIV/0! | Z20: =AVERAGE(W20-$W$4) -> #DIV/0! | AA20: ='Conversion Deio3'!M19 -> #DIV/0! | AB20: ='Conversion Deio3'!M20 -> #DIV/0! | AC20: =AVERAGE(AA20:AB20) -> #DIV/0! | AD20: =AA20-$AC$4 -> #DIV/0! | AE20: =AB20-$AC$4 -> #DIV/0! | AF20: =AC20-$AC$4 -> #DIV/0! | AG20: =#REF! -> #REF! | AH20: =#REF! -> #REF! | AI20: 0 | AJ20: =AG20-$AI$4 -> #REF! | AK20: =AH20-$AI$4 -> #REF! | AL20: =AI20-$AI$4 -> 0 | AM20: =#REF! -> #REF! | AN20: =#REF! -> #REF! | AO20: =AVERAGE(AM20:AN20) -> #REF! | AP20: =AM20-$AO$4 -> #REF! | AQ20: =AN20-$AO$4 -> #REF! | AR20: =AO20-$AO$4 -> #REF!
H21: SD | K21: =_xlfn.STDEV.S(I20:J20) -> #DIV/0! | N21: =_xlfn.STDEV.S(L20:M20) -> #DIV/0! | Q21: =_xlfn.STDEV.S(O20:P20) -> #DIV/0! | T21: =_xlfn.STDEV.S(R20:S20) -> #DIV/0! | W21: =_xlfn.STDEV.S(U20:V20) -> #DIV/0! | Z21: =_xlfn.STDEV.S(X20:Y20) -> #DIV/0! | AC21: =_xlfn.STDEV.S(AA20:AB20) -> #DIV/0! | AF21: =_xlfn.STDEV.S(AD20:AE20) -> #DIV/0!
C38: D3 (%T1+T2net) A | D38: D3 (%T1+T2net) B | E38: fmol/min/mg A | F38: fmol/min/mg B | H38: fmol/min/mg average | J38: SD
T39: Formula
B40: SKNAS1 | C40: =R6+X6 -> 5.4287238 | D40: =S6+Y6 -> 2.9705899 | E40: =C40/$AC$4*2000/120/F6 -> 1.7469481 | F40: =D40/$AC$4*2000/120/F6 -> 0.95592748 | H40: =AVERAGE(E40:F40) -> 1.3514378 | J40: =_xlfn.STDEV.S(E40:F40) -> 0.55933602
B41: SKNAS 2 | C41: =R8+X8 -> 5.701581 | D41: =S8+Y8 -> 9.2341308 | E41: =C41/$AC$4*2000/120/F8 -> 1.8465945 | F41: =D41/$AC$4*2000/120/F8 -> 2.9906959 | H41: =AVERAGE(E41:F41) -> 2.4186452 | J41: =_xlfn.STDEV.S(E41:F41) -> 0.80900188
C42: =R10+X10 -> #DIV/0! | D42: =S10+Y10 -> #DIV/0! | E42: =C42/$AC$4*2000/120/F10 -> #DIV/0! | F42: =D42/$AC$4*2000/120/F10 -> #DIV/0! | H42: =AVERAGE(E42:F42) -> #DIV/0! | J42: =_xlfn.STDEV.S(E42:F42) -> #DIV/0!
C43: =R12+X12 -> #DIV/0! | D43: =S12+Y12 -> #DIV/0! | E43: =C43/$AC$4*2000/120/F12 -> #DIV/0! | F43: =D43/$AC$4*2000/120/F12 -> #DIV/0! | H43: =AVERAGE(E43:F43) -> #DIV/0! | J43: =_xlfn.STDEV.S(E43:F43) -> #DIV/0! | T43: We add 1 nM of cold T3 | W43: 1 nM = 10^6 fmol/L
C44: =R14+X14 -> #DIV/0! | D44: =S14+Y14 -> #DIV/0! | E44: =C44/$AC$4*2000/120/F14 -> #DIV/0! | F44: =D44/$AC$4*2000/120/F14 -> #DIV/0! | H44: =AVERAGE(E44:F44) -> #DIV/0! | J44: =_xlfn.STDEV.S(E44:F44) -> #DIV/0!
C45: =R16+X16 -> #DIV/0! | D45: =S16+Y16 -> #DIV/0! | E45: =C45/$AC$4*2000/120/F16 -> #DIV/0! | F45: =D45/$AC$4*2000/120/F16 -> #DIV/0! | H45: =AVERAGE(E45:F45) -> #DIV/0! | J45: =_xlfn.STDEV.S(E45:F45) -> #DIV/0!
C46: =R18+X18 -> #DIV/0! | D46: =S12+Y12 -> #DIV/0! | E46: =C46/$AC$4*2000/120/F18 -> #DIV/0! | F46: =D46/$AC$4*2000/120/F18 -> #DIV/0! | H46: =AVERAGE(E46:F46) -> #DIV/0! | J46: =_xlfn.STDEV.S(E46:F46) -> #DIV/0!
C47: =R14+X14 -> #DIV/0! | D47: =S18+Y18 -> #DIV/0! | E47: =C47/$AC$4*2000/120/F20 -> #DIV/0! | F47: =D47/$AC$4*2000/120/F20 -> #DIV/0! | H47: =AVERAGE(E47:F47) -> #DIV/0! | J47: =_xlfn.STDEV.S(E47:F47) -> #DIV/0!
